2024-11-04T18:28:59 {"cpu": 0.11279296875, "cpu_total": 16, "cpu_usage": 0.007049560546875, "memory": 2685.0, "memory_total": 19682.0, "memory_usage": 0.13641906310334315, "pipeline_run_id": 11, "pipeline_schedule_id": 3, "pipeline_uuid": "data_generator", "hostname": "49fcf1c5395b", "level": "INFO", "message": "Pipeline data_generator for run 11 in schedule 3 is alive.", "timestamp": 1730744939.612845, "uuid": "0e14880973cf43e2a2e00acb1ef57e77"}
2024-11-04T18:28:59 {"cpu": 0.11279296875, "cpu_total": 16, "cpu_usage": 0.007049560546875, "memory": 2725.0, "memory_total": 19682.0, "memory_usage": 0.1384513768925922, "pipeline_run_id": 11, "pipeline_schedule_id": 3, "pipeline_uuid": "data_generator", "hostname": "49fcf1c5395b", "level": "INFO", "message": "Pipeline data_generator for run 11 in schedule 3 is alive.", "timestamp": 1730744939.717822, "uuid": "967a281d8e3840dabcf3a20b87cd923c"}
2024-11-04T18:28:59 {"block_run_id": 21, "block_uuid": "data_generator", "pipeline_run_id": 11, "pipeline_schedule_id": 3, "pipeline_uuid": "data_generator", "hostname": "49fcf1c5395b", "level": "INFO", "message": "Execute PipelineRun 11, BlockRun 21: pipeline data_generator block data_generator", "timestamp": 1730744939.743214, "uuid": "a610b493930e4dde936e7c4430c99da5"}
2024-11-04T18:29:00 {"block_run_id": 21, "block_uuid": "data_generator", "pipeline_run_id": 11, "pipeline_schedule_id": 3, "pipeline_uuid": "data_generator", "hostname": "49fcf1c5395b", "level": "INFO", "message": "BlockRun 21 (block_uuid: data_generator) completes.", "timestamp": 1730744940.024493, "uuid": "ad5a25e6caf8421a8770efed97c25a6b"}
2024-11-04T18:29:09 {"cpu": 0.11083984375, "cpu_total": 16, "cpu_usage": 0.006927490234375, "memory": 2681.0, "memory_total": 19682.0, "memory_usage": 0.13621583172441826, "pipeline_run_id": 11, "pipeline_schedule_id": 3, "pipeline_uuid": "data_generator", "hostname": "49fcf1c5395b", "level": "INFO", "message": "Pipeline data_generator for run 11 in schedule 3 is alive.", "timestamp": 1730744949.838223, "uuid": "fa871fd7e8ad498eb58830477ac6bb29"}
2024-11-04T18:29:10 {"block_run_id": 22, "block_uuid": "sqlite_exporter", "pipeline_run_id": 11, "pipeline_schedule_id": 3, "pipeline_uuid": "data_generator", "hostname": "49fcf1c5395b", "level": "INFO", "message": "Execute PipelineRun 11, BlockRun 22: pipeline data_generator block sqlite_exporter", "timestamp": 1730744950.005849, "uuid": "9af650785345495d8043678638eed17a"}
2024-11-04T18:29:10 {"block_run_id": 22, "block_uuid": "sqlite_exporter", "pipeline_run_id": 11, "pipeline_schedule_id": 3, "pipeline_uuid": "data_generator", "hostname": "49fcf1c5395b", "level": "EXCEPTION", "message": "BlockRun 22 (block_uuid: sqlite_exporter) failed.", "timestamp": 1730744950.413688, "uuid": "8a81e25619e047bfb8980b1d91279e92", "error": ["Traceback (most recent call last):\n  File \"/usr/local/lib/python3.10/site-packages/mage_ai/data_preparation/executors/block_executor.py\", line 647, in execute\n    result = __execute_with_retry()\n  File \"/usr/local/lib/python3.10/site-packages/mage_ai/shared/retry.py\", line 54, in retry_func\n    raise e\n  File \"/usr/local/lib/python3.10/site-packages/mage_ai/shared/retry.py\", line 38, in retry_func\n    return func(*args, **kwargs)\n  File \"/usr/local/lib/python3.10/site-packages/mage_ai/data_preparation/executors/block_executor.py\", line 621, in __execute_with_retry\n    return self._execute(\n  File \"/usr/local/lib/python3.10/site-packages/mage_ai/data_preparation/executors/block_executor.py\", line 1154, in _execute\n    result = self.block.execute_sync(\n  File \"/usr/local/lib/python3.10/site-packages/mage_ai/data_preparation/models/block/__init__.py\", line 1685, in execute_sync\n    return __execute()\n  File \"/usr/local/lib/python3.10/site-packages/mage_ai/data_preparation/models/block/__init__.py\", line 1662, in __execute\n    raise err\n  File \"/usr/local/lib/python3.10/site-packages/mage_ai/data_preparation/models/block/__init__.py\", line 1564, in __execute\n    output = self.execute_block(\n  File \"/usr/local/lib/python3.10/site-packages/mage_ai/data_preparation/models/block/__init__.py\", line 1904, in execute_block\n    outputs = self._execute_block(\n  File \"/usr/local/lib/python3.10/site-packages/mage_ai/data_preparation/models/block/__init__.py\", line 2067, in _execute_block\n    outputs = self.execute_block_function(\n  File \"/usr/local/lib/python3.10/site-packages/mage_ai/data_preparation/models/block/__init__.py\", line 2163, in execute_block_function\n    output = block_function_updated(*input_vars, **global_vars)\n  File \"<string>\", line 65, in export_data_to_file\nNameError: name 'cusror' is not defined\n"], "error_stack": [["  File \"/usr/local/bin/mage\", line 8, in <module>\n    sys.exit(app())\n", "  File \"/usr/local/lib/python3.10/site-packages/typer/main.py\", line 311, in __call__\n    return get_command(self)(*args, **kwargs)\n", "  File \"/usr/local/lib/python3.10/site-packages/click/core.py\", line 1130, in __call__\n    return self.main(*args, **kwargs)\n", "  File \"/usr/local/lib/python3.10/site-packages/typer/core.py\", line 778, in main\n    return _main(\n", "  File \"/usr/local/lib/python3.10/site-packages/typer/core.py\", line 216, in _main\n    rv = self.invoke(ctx)\n", "  File \"/usr/local/lib/python3.10/site-packages/click/core.py\", line 1657, in invoke\n    return _process_result(sub_ctx.command.invoke(sub_ctx))\n", "  File \"/usr/local/lib/python3.10/site-packages/click/core.py\", line 1404, in invoke\n    return ctx.invoke(self.callback, **ctx.params)\n", "  File \"/usr/local/lib/python3.10/site-packages/click/core.py\", line 760, in invoke\n    return __callback(*args, **kwargs)\n", "  File \"/usr/local/lib/python3.10/site-packages/typer/main.py\", line 683, in wrapper\n    return callback(**use_params)  # type: ignore\n", "  File \"/usr/local/lib/python3.10/site-packages/mage_ai/cli/main.py\", line 147, in start\n    start_server(\n", "  File \"/usr/local/lib/python3.10/site-packages/mage_ai/server/server.py\", line 788, in start_server\n    scheduler_manager.start_scheduler()\n", "  File \"/usr/local/lib/python3.10/site-packages/mage_ai/server/scheduler_manager.py\", line 106, in start_scheduler\n    proc.start()\n", "  File \"/usr/local/lib/python3.10/multiprocessing/process.py\", line 121, in start\n    self._popen = self._Popen(self)\n", "  File \"/usr/local/lib/python3.10/multiprocessing/context.py\", line 224, in _Popen\n    return _default_context.get_context().Process._Popen(process_obj)\n", "  File \"/usr/local/lib/python3.10/multiprocessing/context.py\", line 281, in _Popen\n    return Popen(process_obj)\n", "  File \"/usr/local/lib/python3.10/multiprocessing/popen_fork.py\", line 19, in __init__\n    self._launch(process_obj)\n", "  File \"/usr/local/lib/python3.10/multiprocessing/popen_fork.py\", line 71, in _launch\n    code = process_obj._bootstrap(parent_sentinel=child_r)\n", "  File \"/usr/local/lib/python3.10/multiprocessing/process.py\", line 314, in _bootstrap\n    self.run()\n", "  File \"/usr/local/lib/python3.10/multiprocessing/process.py\", line 108, in run\n    self._target(*self._args, **self._kwargs)\n", "  File \"/usr/local/lib/python3.10/site-packages/mage_ai/orchestration/db/process.py\", line 15, in start_session_and_run\n    results = target(*args)\n", "  File \"/usr/local/lib/python3.10/site-packages/mage_ai/server/scheduler_manager.py\", line 58, in run_scheduler\n    LoopTimeTrigger().start()\n", "  File \"/usr/local/lib/python3.10/site-packages/mage_ai/orchestration/triggers/loop_time_trigger.py\", line 14, in start\n    self.run()\n", "  File \"/usr/local/lib/python3.10/site-packages/mage_ai/orchestration/triggers/time_trigger.py\", line 11, in run\n    schedule_all()\n", "  File \"/usr/local/lib/python3.10/site-packages/mage_ai/orchestration/pipeline_scheduler_original.py\", line 1739, in schedule_all\n    PipelineScheduler(r).schedule()\n", "  File \"/usr/local/lib/python3.10/site-packages/mage_ai/orchestration/db/__init__.py\", line 158, in func_with_rollback\n    return func(*args, **kwargs)\n", "  File \"/usr/local/lib/python3.10/site-packages/mage_ai/orchestration/pipeline_scheduler_original.py\", line 334, in schedule\n    self.__schedule_blocks(block_runs)\n", "  File \"/usr/local/lib/python3.10/site-packages/mage_ai/orchestration/pipeline_scheduler_original.py\", line 641, in __schedule_blocks\n    job_manager.add_job(\n", "  File \"/usr/local/lib/python3.10/site-packages/mage_ai/orchestration/job_manager.py\", line 20, in add_job\n    self.queue.enqueue(job_id, target, *args, **kwargs)\n", "  File \"/usr/local/lib/python3.10/site-packages/mage_ai/orchestration/queue/process_queue.py\", line 121, in enqueue\n    self.start_worker_pool()\n", "  File \"/usr/local/lib/python3.10/site-packages/mage_ai/orchestration/queue/process_queue.py\", line 198, in start_worker_pool\n    self.worker_pool_proc.start()\n", "  File \"/usr/local/lib/python3.10/multiprocessing/process.py\", line 121, in start\n    self._popen = self._Popen(self)\n", "  File \"/usr/local/lib/python3.10/multiprocessing/context.py\", line 224, in _Popen\n    return _default_context.get_context().Process._Popen(process_obj)\n", "  File \"/usr/local/lib/python3.10/multiprocessing/context.py\", line 281, in _Popen\n    return Popen(process_obj)\n", "  File \"/usr/local/lib/python3.10/multiprocessing/popen_fork.py\", line 19, in __init__\n    self._launch(process_obj)\n", "  File \"/usr/local/lib/python3.10/multiprocessing/popen_fork.py\", line 71, in _launch\n    code = process_obj._bootstrap(parent_sentinel=child_r)\n", "  File \"/usr/local/lib/python3.10/multiprocessing/process.py\", line 314, in _bootstrap\n    self.run()\n", "  File \"/usr/local/lib/python3.10/multiprocessing/process.py\", line 108, in run\n    self._target(*self._args, **self._kwargs)\n", "  File \"/usr/local/lib/python3.10/site-packages/mage_ai/orchestration/queue/process_queue.py\", line 351, in poll_job_and_execute\n    worker.start()\n", "  File \"/usr/local/lib/python3.10/multiprocessing/process.py\", line 121, in start\n    self._popen = self._Popen(self)\n", "  File \"/usr/local/lib/python3.10/multiprocessing/context.py\", line 224, in _Popen\n    return _default_context.get_context().Process._Popen(process_obj)\n", "  File \"/usr/local/lib/python3.10/multiprocessing/context.py\", line 281, in _Popen\n    return Popen(process_obj)\n", "  File \"/usr/local/lib/python3.10/multiprocessing/popen_fork.py\", line 19, in __init__\n    self._launch(process_obj)\n", "  File \"/usr/local/lib/python3.10/multiprocessing/popen_fork.py\", line 71, in _launch\n    code = process_obj._bootstrap(parent_sentinel=child_r)\n", "  File \"/usr/local/lib/python3.10/multiprocessing/process.py\", line 314, in _bootstrap\n    self.run()\n", "  File \"/usr/local/lib/python3.10/site-packages/newrelic/api/background_task.py\", line 117, in wrapper\n    return wrapped(*args, **kwargs)\n", "  File \"/usr/local/lib/python3.10/site-packages/mage_ai/orchestration/queue/process_queue.py\", line 315, in run\n    start_session_and_run(args[1], *args[2], **args[3])\n", "  File \"/usr/local/lib/python3.10/site-packages/mage_ai/orchestration/db/process.py\", line 15, in start_session_and_run\n    results = target(*args)\n", "  File \"/usr/local/lib/python3.10/site-packages/mage_ai/orchestration/pipeline_scheduler_original.py\", line 1236, in run_block\n    return ExecutorFactory.get_block_executor(\n", "  File \"/usr/local/lib/python3.10/site-packages/mage_ai/data_preparation/executors/block_executor.py\", line 682, in execute\n    on_failure(\n", "  File \"/usr/local/lib/python3.10/site-packages/mage_ai/orchestration/db/__init__.py\", line 158, in func_with_rollback\n    return func(*args, **kwargs)\n", "  File \"/usr/local/lib/python3.10/site-packages/mage_ai/orchestration/pipeline_scheduler_original.py\", line 465, in on_block_failure\n    self.logger.exception(\n", "  File \"/usr/local/lib/python3.10/site-packages/mage_ai/data_preparation/logging/logger.py\", line 30, in exception\n    self.__send_message('exception', message, **kwargs)\n", "  File \"/usr/local/lib/python3.10/site-packages/mage_ai/data_preparation/logging/logger.py\", line 65, in __send_message\n    data['error_stack'] = traceback.format_stack(),\n"]], "error_stacktrace": ["name 'cusror' is not defined"]}
Traceback (most recent call last):
  File "/usr/local/lib/python3.10/site-packages/mage_ai/data_preparation/executors/block_executor.py", line 647, in execute
    result = __execute_with_retry()
  File "/usr/local/lib/python3.10/site-packages/mage_ai/shared/retry.py", line 54, in retry_func
    raise e
  File "/usr/local/lib/python3.10/site-packages/mage_ai/shared/retry.py", line 38, in retry_func
    return func(*args, **kwargs)
  File "/usr/local/lib/python3.10/site-packages/mage_ai/data_preparation/executors/block_executor.py", line 621, in __execute_with_retry
    return self._execute(
  File "/usr/local/lib/python3.10/site-packages/mage_ai/data_preparation/executors/block_executor.py", line 1154, in _execute
    result = self.block.execute_sync(
  File "/usr/local/lib/python3.10/site-packages/mage_ai/data_preparation/models/block/__init__.py", line 1685, in execute_sync
    return __execute()
  File "/usr/local/lib/python3.10/site-packages/mage_ai/data_preparation/models/block/__init__.py", line 1662, in __execute
    raise err
  File "/usr/local/lib/python3.10/site-packages/mage_ai/data_preparation/models/block/__init__.py", line 1564, in __execute
    output = self.execute_block(
  File "/usr/local/lib/python3.10/site-packages/mage_ai/data_preparation/models/block/__init__.py", line 1904, in execute_block
    outputs = self._execute_block(
  File "/usr/local/lib/python3.10/site-packages/mage_ai/data_preparation/models/block/__init__.py", line 2067, in _execute_block
    outputs = self.execute_block_function(
  File "/usr/local/lib/python3.10/site-packages/mage_ai/data_preparation/models/block/__init__.py", line 2163, in execute_block_function
    output = block_function_updated(*input_vars, **global_vars)
  File "<string>", line 65, in export_data_to_file
NameError: name 'cusror' is not defined
2024-11-04T18:29:20 {"cpu": 0.10888671875, "cpu_total": 16, "cpu_usage": 0.006805419921875, "memory": 2681.0, "memory_total": 19682.0, "memory_usage": 0.13621583172441826, "pipeline_run_id": 11, "pipeline_schedule_id": 3, "pipeline_uuid": "data_generator", "hostname": "49fcf1c5395b", "level": "INFO", "message": "Pipeline data_generator for run 11 in schedule 3 is alive.", "timestamp": 1730744960.019461, "uuid": "27357fbaa4cb40f3ab57367f734bc146"}
